ES6 await为什么建议用try...catch捕获错误？
<p data-pid="KP_Oe2te">用promise的catch的前提是能产生一个promise</p><p data-pid="AYsOcCLV">举个极端点的例子，typo导致的问题</p><p data-pid="EBsDrlOQ">await feych("xxx")</p><p data-pid="fnGVYLEN">我不小心把fetch打成feych了，如果我把await给直接try catch起来了，那么是能捕获的，会告诉我feych没有被定义</p><p data-pid="JilMw6Qk">但如果我用的是promise的catch，因为这种情况下根本不能生成一个promise，就没用了，代码走到这里抛了个undefined就走不下去了</p><figure data-size="normal"><noscript><img src="https://pic1.zhimg.com/v2-7f258d1cdd5ef7a58a08e53f7cff29ec_720w.jpg?source=3af55fa1" data-rawwidth="1305" data-rawheight="2048" data-size="normal" data-default-watermark-src="https://pic3.zhimg.com/v2-139633780bfb305ed5920aaba6dde609_720w.jpg?source=3af55fa1" class="origin_image zh-lightbox-thumb" width="1305" data-original="https://pic3.zhimg.com/v2-7f258d1cdd5ef7a58a08e53f7cff29ec_r.jpg?source=3af55fa1"></noscript><img src="data:image/svg+xml;utf8,&lt;svg%20xmlns='http://www.w3.org/2000/svg'%20width='1305'%20height='2048'&gt;&lt;/svg&gt;" data-rawwidth="1305" data-rawheight="2048" data-size="normal" data-default-watermark-src="https://pic3.zhimg.com/v2-139633780bfb305ed5920aaba6dde609_720w.jpg?source=3af55fa1" class="origin_image zh-lightbox-thumb lazy" width="1305" data-original="https://pic3.zhimg.com/v2-7f258d1cdd5ef7a58a08e53f7cff29ec_r.jpg?source=3af55fa1" data-actualsrc="https://pic1.zhimg.com/v2-7f258d1cdd5ef7a58a08e53f7cff29ec_720w.jpg?source=3af55fa1"></figure><p data-pid="c1vAcDEL">这个案例就告诉我们promise的catch是非常有局限性的，它好用，但不是全能的，它设计是为了处理promise生成但没能正确处理完成的情况，但不能应对无法生成promise的问题</p><p></p>
1642484119